<?xml version="1.0" encoding="UTF-8"?>
<testng-results ignored="0" total="1" passed="0" failed="1" skipped="0">
  <reporter-output>
    <line>
      <![CDATA[Old report backed up to folder D:\Development\Eclipse-Workspaces\WithRituRaj\TestFramework2\Test-Reports//20May24_20.24.26.563//]]>
    </line>
  </reporter-output>
  <suite started-at="2024-05-20T20:24:27 IST" name="Suite" finished-at="2024-05-20T20:24:34 IST" duration-ms="7442">
    <groups>
    </groups>
    <test started-at="2024-05-20T20:24:27 IST" name="Test" finished-at="2024-05-20T20:24:34 IST" duration-ms="7442">
      <class name="com.tests.SauceInvalidLoginTest">
        <test-method is-config="true" signature="preSuite()[pri:0, instance:com.tests.SauceInvalidLoginTest@393671df]" started-at="2024-05-20T20:24:26 IST" name="preSuite" finished-at="2024-05-20T20:24:27 IST" duration-ms="412" status="PASS">
          <reporter-output>
            <line>
              <![CDATA[Old report backed up to folder D:\Development\Eclipse-Workspaces\WithRituRaj\TestFramework2\Test-Reports//20May24_20.24.26.563//]]>
            </line>
          </reporter-output>
        </test-method> <!-- preSuite -->
        <test-method is-config="true" signature="init()[pri:0, instance:com.tests.SauceInvalidLoginTest@393671df]" started-at="2024-05-20T20:24:27 IST" name="init" finished-at="2024-05-20T20:24:31 IST" duration-ms="3969" status="PASS">
          <reporter-output>
          </reporter-output>
        </test-method> <!-- init -->
        <test-method signature="invalidLoginTest()[pri:0, instance:com.tests.SauceInvalidLoginTest@393671df]" started-at="2024-05-20T20:24:31 IST" name="invalidLoginTest" finished-at="2024-05-20T20:24:33 IST" duration-ms="2576" status="FAIL">
          <exception class="java.lang.AssertionError">
            <message>
              <![CDATA[Error Message Did not Match expected [Epic sadface: Sorry, this user has been locked out.XYZ] but found [Epic sadface: Sorry, this user has been locked out.]]]>
            </message>
            <full-stacktrace>
              <![CDATA[java.lang.AssertionError: Error Message Did not Match expected [Epic sadface: Sorry, this user has been locked out.XYZ] but found [Epic sadface: Sorry, this user has been locked out.]
at org.testng.Assert.fail(Assert.java:99)
at org.testng.Assert.failNotEquals(Assert.java:1037)
at org.testng.Assert.assertEqualsImpl(Assert.java:140)
at org.testng.Assert.assertEquals(Assert.java:122)
at org.testng.Assert.assertEquals(Assert.java:629)
at com.tests.SauceInvalidLoginTest.invalidLoginTest(SauceInvalidLoginTest.java:16)
at java.base/jdk.internal.reflect.NativeMethodAccessorImpl.invoke0(Native Method)
at java.base/jdk.internal.reflect.NativeMethodAccessorImpl.invoke(NativeMethodAccessorImpl.java:77)
at java.base/jdk.internal.reflect.DelegatingMethodAccessorImpl.invoke(DelegatingMethodAccessorImpl.java:43)
at java.base/java.lang.reflect.Method.invoke(Method.java:568)
at org.testng.internal.MethodInvocationHelper.invokeMethod(MethodInvocationHelper.java:133)
at org.testng.internal.TestInvoker.invokeMethod(TestInvoker.java:598)
at org.testng.internal.TestInvoker.invokeTestMethod(TestInvoker.java:173)
at org.testng.internal.MethodRunner.runInSequence(MethodRunner.java:46)
at org.testng.internal.TestInvoker$MethodInvocationAgent.invoke(TestInvoker.java:824)
at org.testng.internal.TestInvoker.invokeTestMethods(TestInvoker.java:146)
at org.testng.internal.TestMethodWorker.invokeTestMethods(TestMethodWorker.java:146)
at org.testng.internal.TestMethodWorker.run(TestMethodWorker.java:128)
at java.base/java.util.ArrayList.forEach(ArrayList.java:1511)
at org.testng.TestRunner.privateRun(TestRunner.java:794)
at org.testng.TestRunner.run(TestRunner.java:596)
at org.testng.SuiteRunner.runTest(SuiteRunner.java:377)
at org.testng.SuiteRunner.runSequentially(SuiteRunner.java:371)
at org.testng.SuiteRunner.privateRun(SuiteRunner.java:332)
at org.testng.SuiteRunner.run(SuiteRunner.java:276)
at org.testng.SuiteRunnerWorker.runSuite(SuiteRunnerWorker.java:53)
at org.testng.SuiteRunnerWorker.run(SuiteRunnerWorker.java:96)
at org.testng.TestNG.runSuitesSequentially(TestNG.java:1212)
at org.testng.TestNG.runSuitesLocally(TestNG.java:1134)
at org.testng.TestNG.runSuites(TestNG.java:1063)
at org.testng.TestNG.run(TestNG.java:1031)
at org.testng.remote.AbstractRemoteTestNG.run(AbstractRemoteTestNG.java:115)
at org.testng.remote.RemoteTestNG.initAndRun(RemoteTestNG.java:251)
at org.testng.remote.RemoteTestNG.main(RemoteTestNG.java:77)
]]>
            </full-stacktrace>
          </exception> <!-- java.lang.AssertionError -->
          <reporter-output>
          </reporter-output>
        </test-method> <!-- invalidLoginTest -->
        <test-method is-config="true" signature="tearDown()[pri:0, instance:com.tests.SauceInvalidLoginTest@393671df]" started-at="2024-05-20T20:24:34 IST" name="tearDown" finished-at="2024-05-20T20:24:34 IST" duration-ms="498" status="PASS">
          <reporter-output>
          </reporter-output>
        </test-method> <!-- tearDown -->
      </class> <!-- com.tests.SauceInvalidLoginTest -->
    </test> <!-- Test -->
  </suite> <!-- Suite -->
</testng-results>
